<?xml version="1.0" ?>
<!-- =================================================================================== -->
<!-- |    This document was autogenerated by xacro from movo.urdf.xacro                | -->
<!-- |    EDITING THIS FILE BY HAND IS NOT RECOMMENDED                                 | -->
<!-- =================================================================================== -->
<!--
Software License Agreement (BSD)
\file      movo.urdf.xacro
\authors   Patrick Hussey
\copyright Copyright (c) 2017, Kinova Robotics inc. All rights reserved.
Redistribution and use in source and binary forms, with or without modification,
are permitted provided that the following conditions are met:
    * Redistributions of source code must retain the above copyright notice,
      this list of conditions and the following disclaimer.
    * Redistributions in binary form must reproduce the above copyright notice,
      this list of conditions and the following disclaimer in the documentation
      and/or other materials provided with the distribution.
    * Neither the name of the copyright holder nor the names of its contributors
      may be used to endorse or promote products derived from this software
      without specific prior written permission.
THIS SOFTWARE IS PROVIDED BY THE COPYRIGHT HOLDERS AND CONTRIBUTORS 
"AS IS" AND ANY EXPRESS OR IMPLIED WARRANTIES, INCLUDING, BUT NOT 
LIMITED TO, THE IMPLIED WARRANTIES OF MERCHANTABILITY AND FITNESS FOR 
A PARTICULAR PURPOSE ARE DISCLAIMED. IN NO EVENT SHALL THE COPYRIGHT HOLDER OR 
CONTRIBUTORS BE LIABLE FOR ANY DIRECT, INDIRECT, INCIDENTAL, SPECIAL, 
EXEMPLARY, OR CONSEQUENTIAL DAMAGES (INCLUDING, BUT NOT LIMITED TO, 
PROCUREMENT OF SUBSTITUTE GOODS OR SERVICES; LOSS OF USE, DATA, OR 
PROFITS; OR BUSINESS INTERRUPTION) HOWEVER CAUSED AND ON ANY THEORY OF 
LIABILITY, WHETHER IN CONTRACT, STRICT LIABILITY, OR TORT (INCLUDING 
NEGLIGENCE OR OTHERWISE) ARISING IN ANY WAY OUT OF THE USE OF THIS 
SOFTWARE, EVEN IF ADVISED OF THE POSSIBILITY OF SUCH DAMAGE.
-->
<robot name="movo" xmlns:xacro="http://ros.org/wiki/xacro">
  <link name="root"/>
  <link name="root1"/>
  <link name="root2"/>
  <link name="root3"/>
  <link name="root4"/>
  <link name="root5"/>
  <link name="root6"/>
  <joint name="x_axis_joint" type="prismatic">
    <parent link="root"/>
    <child link="root1"/>
    <axis xyz="1 0 0"/>
    <limit lower="-10" upper="10" velocity="0.50"/>
    <dynamics damping="10.0" friction="10"/>
  </joint>
  <joint name="y_axis_joint" type="prismatic">
    <parent link="root1"/>
    <child link="root2"/>
    <axis xyz="0 1 0"/>
    <limit lower="-10" upper="10" velocity="0.50"/>
    <dynamics damping="10.0" friction="10"/>
  </joint>
  <joint name="z_axis_joint" type="prismatic">
    <parent link="root2"/>
    <child link="root3"/>
    <axis xyz="0 0 1"/>
    <limit lower="-10" upper="10" velocity="0.50"/>
    <dynamics damping="10.0" friction="10"/>
  </joint>
  <joint name="r_rotation_joint" type="continuous">
    <parent link="root3"/>
    <child link="root4"/>
    <axis xyz="1 0 0"/>
    <dynamics damping="10.0" friction="1"/>
  </joint>
  <joint name="p_rotation_joint" type="continuous">
    <parent link="root4"/>
    <child link="root5"/>
    <axis xyz="0 1 0"/>
    <dynamics damping="10.0" friction="1"/>
  </joint>
  <joint name="y_rotation_joint" type="continuous">
    <parent link="root5"/>
    <child link="root6"/>
    <axis xyz="0 0 1"/>
    <dynamics damping="10.0" friction="1"/>
  </joint>
  <joint name="right_ee_fixed_joint" type="fixed">
    <parent link="root6"/>
    <child link="right_ee_link"/>
  </joint>
  <link name="right_ee_link"/>
  <joint name="right_gripper_base_joint" type="fixed">
    <parent link="right_ee_link"/>
    <child link="right_gripper_base_link"/>
    <origin rpy="-3.14159265 1.570796325 0" xyz="-0.16 0 0"/>
  </joint>
  <link name="right_gripper_base_link">
    <visual>
      <geometry>
        <mesh filename="movo_description/meshes/manipulation/kinova_grippers/visual/kg3_base_link.dae"/>
      </geometry>
    </visual>
    <collision>
      <geometry>
        <mesh filename="movo_description/meshes/manipulation/kinova_grippers/collision/kg3_base_link.stl"/>
      </geometry>
    </collision>
    <inertial>
      <mass value="0.799312"/>
      <origin xyz="0.000007 -0.005175 -0.067280"/>
      <inertia ixx="0.000790" ixy="0.000000" ixz="0.000004" iyx="0.000000" iyy="0.000650" iyz="0.000003" izx="0.000004"
               izy="0.000003" izz="0.000823"/>
    </inertial>
  </link>
  <joint name="right_gripper_finger1_joint" type="revolute">
    <parent link="right_gripper_base_link"/>
    <child link="right_gripper_finger1_knuckle_link"/>
    <axis xyz="0 0 1"/>
    <origin rpy="1.4676 -0.0092813 -1.7501" xyz="-0.0027954 0.031318 -0.11464"/>
    <limit damping="0.005" effort="3.0" friction="0.005" lower="0.0" upper="0.986111027" stepSize="1.0"/>
  </joint>
  <link name="right_gripper_finger1_knuckle_link">
    <visual>
      <geometry>
        <mesh filename="movo_description/meshes/manipulation/kinova_grippers/visual/finger_knuckle.dae"/>
      </geometry>
    </visual>
    <collision>
      <geometry>
        <mesh filename="movo_description/meshes/manipulation/kinova_grippers/collision/finger_knuckle.stl"/>
      </geometry>
    </collision>
    <inertial>
      <mass value="0.009127"/>
      <origin xyz="-0.016752 -0.013874 0.0"/>
      <inertia ixx="0.000002" ixy="0.000001" ixz="0.000000" iyx="0.000001" iyy="0.000001" iyz="0.000000" izx="0.000000"
               izy="0.000000" izz="0.000002"/>
    </inertial>
  </link>
  <joint name="right_gripper_finger2_joint" type="revolute">
    <parent link="right_gripper_base_link"/>
    <child link="right_gripper_finger2_knuckle_link"/>
    <axis xyz="0 0 1"/>
    <origin rpy="1.570796325 0 1.7555" xyz="0.022289 -0.027253 -0.11471"/>
    <limit damping="0.005" effort="3.0" friction="0.005" lower="0.0" upper="0.986111027" stepSize="1.0"/>
    <mimic joint="right_gripper_finger1_joint"/>
  </joint>
  <link name="right_gripper_finger2_knuckle_link">
    <visual>
      <geometry>
        <mesh filename="movo_description/meshes/manipulation/kinova_grippers/visual/finger_knuckle.dae"/>
      </geometry>
    </visual>
    <collision>
      <geometry>
        <mesh filename="movo_description/meshes/manipulation/kinova_grippers/collision/finger_knuckle.stl"/>
      </geometry>
    </collision>
    <inertial>
      <mass value="0.009127"/>
      <origin xyz="-0.016752 -0.013874 0.0"/>
      <inertia ixx="0.000002" ixy="0.000001" ixz="0.000000" iyx="0.000001" iyy="0.000001" iyz="0.000000" izx="0.000000"
               izy="0.000000" izz="0.000002"/>
    </inertial>
  </link>
  <joint name="right_gripper_finger3_joint" type="revolute">
    <parent link="right_gripper_base_link"/>
    <child link="right_gripper_finger3_knuckle_link"/>
    <axis xyz="0 0 1"/>
    <origin rpy="1.570796325 0 1.3861" xyz="-0.022284 -0.027223 -0.11473"/>
    <limit damping="0.005" effort="3.0" friction="0.005" lower="0.0" upper="0.986111027" stepSize="1.0"/>
    <mimic joint="right_gripper_finger1_joint"/>
  </joint>
  <link name="right_gripper_finger3_knuckle_link">
    <visual>
      <geometry>
        <mesh filename="movo_description/meshes/manipulation/kinova_grippers/visual/finger_knuckle.dae"/>
      </geometry>
    </visual>
    <collision>
      <geometry>
        <mesh filename="movo_description/meshes/manipulation/kinova_grippers/collision/finger_knuckle.stl"/>
      </geometry>
    </collision>
    <inertial>
      <mass value="0.009127"/>
      <origin xyz="-0.016752 -0.013874 0.0"/>
      <inertia ixx="0.000002" ixy="0.000001" ixz="0.000000" iyx="0.000001" iyy="0.000001" iyz="0.000000" izx="0.000000"
               izy="0.000000" izz="0.000002"/>
    </inertial>
  </link>
  <joint name="right_gripper_finger1_finger_tip_joint" type="fixed">
    <parent link="right_gripper_finger1_knuckle_link"/>
    <child link="right_gripper_finger1_finger_tip_link"/>
    <origin rpy="0 0 0" xyz="-0.0245981 -0.036051 0.0"/>
  </joint>
  <link name="right_gripper_finger1_finger_tip_link">
    <visual>
      <geometry>
        <mesh filename="movo_description/meshes/manipulation/kinova_grippers/visual/finger_tip.dae"/>
      </geometry>
    </visual>
    <collision>
      <geometry>
        <mesh filename="movo_description/meshes/manipulation/kinova_grippers/collision/finger_tip1.stl"/>
      </geometry>
    </collision>
    <collision>
      <geometry>
        <mesh filename="movo_description/meshes/manipulation/kinova_grippers/collision/finger_tip2.stl"/>
      </geometry>
    </collision>
    <collision>
      <geometry>
        <mesh filename="movo_description/meshes/manipulation/kinova_grippers/collision/finger_tip3.stl"/>
      </geometry>
    </collision>
    <collision>
      <geometry>
        <mesh filename="movo_description/meshes/manipulation/kinova_grippers/collision/finger_tip4.stl"/>
      </geometry>
    </collision>
    <collision>
      <geometry>
        <mesh filename="movo_description/meshes/manipulation/kinova_grippers/collision/finger_tip5.stl"/>
      </geometry>
    </collision>
    <collision>
      <geometry>
        <mesh filename="movo_description/meshes/manipulation/kinova_grippers/collision/finger_tip6.stl"/>
      </geometry>
    </collision>
    <inertial>
      <mass value="0.012690"/>
      <origin xyz="-0.011926 -0.009701 0.0"/>
      <inertia ixx="0.000002" ixy="0.000001" ixz="0.000000" iyx="0.000001" iyy="0.000001" iyz="0.000000" izx="0.000000"
               izy="0.000000" izz="0.000002"/>
    </inertial>
  </link>
  <joint name="right_gripper_finger2_finger_tip_joint" type="fixed">
    <parent link="right_gripper_finger2_knuckle_link"/>
    <child link="right_gripper_finger2_finger_tip_link"/>
    <origin rpy="0 0 0" xyz="-0.0245981 -0.036051 0.0"/>
  </joint>
  <link name="right_gripper_finger2_finger_tip_link">
    <visual>
      <geometry>
        <mesh filename="movo_description/meshes/manipulation/kinova_grippers/visual/finger_tip.dae"/>
      </geometry>
    </visual>
    <collision>
      <geometry>
        <mesh filename="movo_description/meshes/manipulation/kinova_grippers/collision/finger_tip1.stl"/>
      </geometry>
    </collision>
    <collision>
      <geometry>
        <mesh filename="movo_description/meshes/manipulation/kinova_grippers/collision/finger_tip2.stl"/>
      </geometry>
    </collision>
    <collision>
      <geometry>
        <mesh filename="movo_description/meshes/manipulation/kinova_grippers/collision/finger_tip3.stl"/>
      </geometry>
    </collision>
    <collision>
      <geometry>
        <mesh filename="movo_description/meshes/manipulation/kinova_grippers/collision/finger_tip4.stl"/>
      </geometry>
    </collision>
    <collision>
      <geometry>
        <mesh filename="movo_description/meshes/manipulation/kinova_grippers/collision/finger_tip5.stl"/>
      </geometry>
    </collision>
    <collision>
      <geometry>
        <mesh filename="movo_description/meshes/manipulation/kinova_grippers/collision/finger_tip6.stl"/>
      </geometry>
    </collision>
    <inertial>
      <mass value="0.012690"/>
      <origin xyz="-0.011926 -0.009701 0.0"/>
      <inertia ixx="0.000002" ixy="0.000001" ixz="0.000000" iyx="0.000001" iyy="0.000001" iyz="0.000000" izx="0.000000"
               izy="0.000000" izz="0.000002"/>
    </inertial>
  </link>
  <joint name="right_gripper_finger3_finger_tip_joint" type="fixed">
    <parent link="right_gripper_finger3_knuckle_link"/>
    <child link="right_gripper_finger3_finger_tip_link"/>
    <origin rpy="0 0 0" xyz="-0.0245981 -0.036051 0.0"/>
  </joint>
  <link name="right_gripper_finger3_finger_tip_link">
    <visual>
      <geometry>
        <mesh filename="movo_description/meshes/manipulation/kinova_grippers/visual/finger_tip.dae"/>
      </geometry>
    </visual>
    <collision>
      <geometry>
        <mesh filename="movo_description/meshes/manipulation/kinova_grippers/collision/finger_tip1.stl"/>
      </geometry>
    </collision>
    <collision>
      <geometry>
        <mesh filename="movo_description/meshes/manipulation/kinova_grippers/collision/finger_tip2.stl"/>
      </geometry>
    </collision>
    <collision>
      <geometry>
        <mesh filename="movo_description/meshes/manipulation/kinova_grippers/collision/finger_tip3.stl"/>
      </geometry>
    </collision>
    <collision>
      <geometry>
        <mesh filename="movo_description/meshes/manipulation/kinova_grippers/collision/finger_tip4.stl"/>
      </geometry>
    </collision>
    <collision>
      <geometry>
        <mesh filename="movo_description/meshes/manipulation/kinova_grippers/collision/finger_tip5.stl"/>
      </geometry>
    </collision>
    <collision>
      <geometry>
        <mesh filename="movo_description/meshes/manipulation/kinova_grippers/collision/finger_tip6.stl"/>
      </geometry>
    </collision>
    <inertial>
      <mass value="0.012690"/>
      <origin xyz="-0.011926 -0.009701 0.0"/>
      <inertia ixx="0.000002" ixy="0.000001" ixz="0.000000" iyx="0.000001" iyy="0.000001" iyz="0.000000" izx="0.000000"
               izy="0.000000" izz="0.000002"/>
    </inertial>
  </link>
</robot>

