<?xml version="1.0" ?>
<robot name="partnet_6f36520144753550f91663a74ccd2338">
	<link name="base"/>
	<link name="link_0">
		<visual name="caster_stem-88">
			<origin xyz="-0.004824560353282527 0.6854306951624354 -0.6261094488673553"/>
			<geometry>
				<mesh filename="textured_objs/original-1.obj"/>
			</geometry>
		</visual>
		<collision>
			<origin xyz="-0.004824560353282527 0.6854306951624354 -0.6261094488673553"/>
			<geometry>
				<mesh filename="textured_objs/original-1.obj"/>
			</geometry>
		</collision>
	</link>
	<joint name="joint_0" type="continuous">
		<origin xyz="0.004824560353282527 -0.6854306951624354 0.6261094488673553"/>
		<axis xyz="0 1 0"/>
		<child link="link_0"/>
		<parent link="link_16"/>
	</joint>
	<link name="link_1">
		<visual name="wheel-89">
			<origin xyz="0 0.787426 -0.6367505"/>
			<geometry>
				<mesh filename="textured_objs/original-13.obj"/>
			</geometry>
		</visual>
		<collision>
			<origin xyz="0 0.787426 -0.6367505"/>
			<geometry>
				<mesh filename="textured_objs/original-13.obj"/>
			</geometry>
		</collision>
	</link>
	<joint name="joint_1" type="continuous">
		<origin xyz="-0.004824560353282527 -0.10199530483756458 0.010641051132644685"/>
		<axis xyz="1 0 0"/>
		<child link="link_1"/>
		<parent link="link_0"/>
	</joint>
	<link name="link_2">
		<visual name="wheel-90">
			<origin xyz="0 0.787426 -0.6367505"/>
			<geometry>
				<mesh filename="textured_objs/original-22.obj"/>
			</geometry>
		</visual>
		<collision>
			<origin xyz="0 0.787426 -0.6367505"/>
			<geometry>
				<mesh filename="textured_objs/original-22.obj"/>
			</geometry>
		</collision>
	</link>
	<joint name="joint_2" type="continuous">
		<origin xyz="-0.004824560353282527 -0.10199530483756458 0.010641051132644685"/>
		<axis xyz="1 0 0"/>
		<child link="link_2"/>
		<parent link="link_0"/>
	</joint>
	<link name="link_3">
		<visual name="caster_stem-85">
			<origin xyz="0.4752625738710319 0.6813977063051926 -0.2731863872516069"/>
			<geometry>
				<mesh filename="textured_objs/original-3.obj"/>
			</geometry>
		</visual>
		<collision>
			<origin xyz="0.4752625738710319 0.6813977063051926 -0.2731863872516069"/>
			<geometry>
				<mesh filename="textured_objs/original-3.obj"/>
			</geometry>
		</collision>
	</link>
	<joint name="joint_3" type="continuous">
		<origin xyz="-0.4752625738710319 -0.6813977063051926 0.2731863872516069"/>
		<axis xyz="0 1 0"/>
		<child link="link_3"/>
		<parent link="link_16"/>
	</joint>
	<link name="link_4">
		<visual name="wheel-86">
			<origin xyz="0.5200274031646904 0.7874214223528662 -0.17040334689669234"/>
			<geometry>
				<mesh filename="textured_objs/original-23.obj"/>
			</geometry>
		</visual>
		<collision>
			<origin xyz="0.5200274031646904 0.7874214223528662 -0.17040334689669234"/>
			<geometry>
				<mesh filename="textured_objs/original-23.obj"/>
			</geometry>
		</collision>
	</link>
	<joint name="joint_4" type="continuous">
		<origin xyz="-0.04476482929365855 -0.10602371604767358 -0.10278304035491453"/>
		<axis xyz="-0.31143727124422005 3.465755326456095e-05 -0.9502667124964487"/>
		<child link="link_4"/>
		<parent link="link_3"/>
	</joint>
	<link name="link_5">
		<visual name="wheel-87">
			<origin xyz="0.5200274031646904 0.7874214223528662 -0.17040334689669234"/>
			<geometry>
				<mesh filename="textured_objs/original-18.obj"/>
			</geometry>
		</visual>
		<collision>
			<origin xyz="0.5200274031646904 0.7874214223528662 -0.17040334689669234"/>
			<geometry>
				<mesh filename="textured_objs/original-18.obj"/>
			</geometry>
		</collision>
	</link>
	<joint name="joint_5" type="continuous">
		<origin xyz="-0.04476482929365855 -0.10602371604767358 -0.10278304035491453"/>
		<axis xyz="-0.31143727124422005 3.465755326456095e-05 -0.9502667124964487"/>
		<child link="link_5"/>
		<parent link="link_3"/>
	</joint>
	<link name="link_6">
		<visual name="caster_stem-82">
			<origin xyz="0.29202366712906264 0.6795459934029324 0.2836826633212231"/>
			<geometry>
				<mesh filename="textured_objs/original-10.obj"/>
			</geometry>
		</visual>
		<collision>
			<origin xyz="0.29202366712906264 0.6795459934029324 0.2836826633212231"/>
			<geometry>
				<mesh filename="textured_objs/original-10.obj"/>
			</geometry>
		</collision>
	</link>
	<joint name="joint_6" type="continuous">
		<origin xyz="-0.29202366712906264 -0.6795459934029324 -0.2836826633212231"/>
		<axis xyz="0 1 0"/>
		<child link="link_6"/>
		<parent link="link_16"/>
	</joint>
	<link name="link_7">
		<visual name="wheel-83">
			<origin xyz="0.24637015095313 0.7874259922691701 0.33729412690697513"/>
			<geometry>
				<mesh filename="textured_objs/original-2.obj"/>
			</geometry>
		</visual>
		<collision>
			<origin xyz="0.24637015095313 0.7874259922691701 0.33729412690697513"/>
			<geometry>
				<mesh filename="textured_objs/original-2.obj"/>
			</geometry>
		</collision>
	</link>
	<joint name="joint_7" type="continuous">
		<origin xyz="0.045653516175932635 -0.10787999886623767 -0.05361146358575203"/>
		<axis xyz="-0.8075151932136608 -5.378786135316403e-06 0.5898467705261876"/>
		<child link="link_7"/>
		<parent link="link_6"/>
	</joint>
	<link name="link_8">
		<visual name="wheel-84">
			<origin xyz="0.24637015095313 0.7874259922691701 0.33729412690697513"/>
			<geometry>
				<mesh filename="textured_objs/original-14.obj"/>
			</geometry>
		</visual>
		<collision>
			<origin xyz="0.24637015095313 0.7874259922691701 0.33729412690697513"/>
			<geometry>
				<mesh filename="textured_objs/original-14.obj"/>
			</geometry>
		</collision>
	</link>
	<joint name="joint_8" type="continuous">
		<origin xyz="0.045653516175932635 -0.10787999886623767 -0.05361146358575203"/>
		<axis xyz="-0.8075151932136608 -5.378786135316403e-06 0.5898467705261876"/>
		<child link="link_8"/>
		<parent link="link_6"/>
	</joint>
	<link name="link_9">
		<visual name="caster_stem-79">
			<origin xyz="-0.30236794036172887 0.8301428355032825 0.27784855936927083"/>
			<geometry>
				<mesh filename="textured_objs/original-15.obj"/>
			</geometry>
		</visual>
		<collision>
			<origin xyz="-0.30236794036172887 0.8301428355032825 0.27784855936927083"/>
			<geometry>
				<mesh filename="textured_objs/original-15.obj"/>
			</geometry>
		</collision>
	</link>
	<joint name="joint_9" type="continuous">
		<origin xyz="0.30236794036172887 -0.8301428355032825 -0.27784855936927083"/>
		<axis xyz="0 1 0"/>
		<child link="link_9"/>
		<parent link="link_16"/>
	</joint>
	<link name="link_10">
		<visual name="wheel-80">
			<origin xyz="-0.25018009075653685 0.7874265 0.34629613868353354"/>
			<geometry>
				<mesh filename="textured_objs/original-35.obj"/>
			</geometry>
		</visual>
		<collision>
			<origin xyz="-0.25018009075653685 0.7874265 0.34629613868353354"/>
			<geometry>
				<mesh filename="textured_objs/original-35.obj"/>
			</geometry>
		</collision>
	</link>
	<joint name="joint_10" type="continuous">
		<origin xyz="-0.052187849605192016 0.042716335503282465 -0.06844757931426271"/>
		<axis xyz="-0.8105932913436219 0 -0.5856095252202734"/>
		<child link="link_10"/>
		<parent link="link_9"/>
	</joint>
	<link name="link_11">
		<visual name="wheel-81">
			<origin xyz="-0.25018009075653685 0.7874265 0.34629613868353354"/>
			<geometry>
				<mesh filename="textured_objs/original-36.obj"/>
			</geometry>
		</visual>
		<collision>
			<origin xyz="-0.25018009075653685 0.7874265 0.34629613868353354"/>
			<geometry>
				<mesh filename="textured_objs/original-36.obj"/>
			</geometry>
		</collision>
	</link>
	<joint name="joint_11" type="continuous">
		<origin xyz="-0.052187849605192016 0.042716335503282465 -0.06844757931426271"/>
		<axis xyz="-0.8105932913436219 0 -0.5856095252202734"/>
		<child link="link_11"/>
		<parent link="link_9"/>
	</joint>
	<link name="link_12">
		<visual name="caster_stem-76">
			<origin xyz="-0.47971523710225916 0.685311767391215 -0.26765977873258134"/>
			<geometry>
				<mesh filename="textured_objs/original-11.obj"/>
			</geometry>
		</visual>
		<collision>
			<origin xyz="-0.47971523710225916 0.685311767391215 -0.26765977873258134"/>
			<geometry>
				<mesh filename="textured_objs/original-11.obj"/>
			</geometry>
		</collision>
	</link>
	<joint name="joint_12" type="continuous">
		<origin xyz="0.47971523710225916 -0.685311767391215 0.26765977873258134"/>
		<axis xyz="0 1 0"/>
		<child link="link_12"/>
		<parent link="link_16"/>
	</joint>
	<link name="link_13">
		<visual name="wheel-77">
			<origin xyz="-0.535542535061673 0.7874356648073184 -0.1725515112167239"/>
			<geometry>
				<mesh filename="textured_objs/original-33.obj"/>
			</geometry>
		</visual>
		<collision>
			<origin xyz="-0.535542535061673 0.7874356648073184 -0.1725515112167239"/>
			<geometry>
				<mesh filename="textured_objs/original-33.obj"/>
			</geometry>
		</collision>
	</link>
	<joint name="joint_13" type="continuous">
		<origin xyz="0.05582729795941388 -0.10212389741610339 -0.09510826751585744"/>
		<axis xyz="0.3065887364620658 -6.41029691319091e-05 -0.951842078585205"/>
		<child link="link_13"/>
		<parent link="link_12"/>
	</joint>
	<link name="link_14">
		<visual name="wheel-78">
			<origin xyz="-0.535542535061673 0.7874356648073184 -0.1725515112167239"/>
			<geometry>
				<mesh filename="textured_objs/original-34.obj"/>
			</geometry>
		</visual>
		<collision>
			<origin xyz="-0.535542535061673 0.7874356648073184 -0.1725515112167239"/>
			<geometry>
				<mesh filename="textured_objs/original-34.obj"/>
			</geometry>
		</collision>
	</link>
	<joint name="joint_14" type="continuous">
		<origin xyz="0.05582729795941388 -0.10212389741610339 -0.09510826751585744"/>
		<axis xyz="0.3065887364620658 -6.41029691319091e-05 -0.951842078585205"/>
		<child link="link_14"/>
		<parent link="link_12"/>
	</joint>
	<link name="link_15">
		<visual name="back_soft_surface-105">
			<origin xyz="-0.0069497679964117265 0 -0.118190120704646"/>
			<geometry>
				<mesh filename="textured_objs/original-19.obj"/>
			</geometry>
		</visual>
		<visual name="back_soft_surface-105">
			<origin xyz="-0.0069497679964117265 0 -0.118190120704646"/>
			<geometry>
				<mesh filename="textured_objs/original-4.obj"/>
			</geometry>
		</visual>
		<visual name="armrest_soft_surface-99">
			<origin xyz="-0.0069497679964117265 0 -0.118190120704646"/>
			<geometry>
				<mesh filename="textured_objs/original-26.obj"/>
			</geometry>
		</visual>
		<visual name="arm_vertical_bar-100">
			<origin xyz="-0.0069497679964117265 0 -0.118190120704646"/>
			<geometry>
				<mesh filename="textured_objs/new-4.obj"/>
			</geometry>
		</visual>
		<visual name="arm_horizontal_bar-101">
			<origin xyz="-0.0069497679964117265 0 -0.118190120704646"/>
			<geometry>
				<mesh filename="textured_objs/new-5.obj"/>
			</geometry>
		</visual>
		<visual name="other_leaf-103">
			<origin xyz="-0.0069497679964117265 0 -0.118190120704646"/>
			<geometry>
				<mesh filename="textured_objs/original-29.obj"/>
			</geometry>
		</visual>
		<visual name="other_leaf-103">
			<origin xyz="-0.0069497679964117265 0 -0.118190120704646"/>
			<geometry>
				<mesh filename="textured_objs/original-16.obj"/>
			</geometry>
		</visual>
		<visual name="armrest_soft_surface-94">
			<origin xyz="-0.0069497679964117265 0 -0.118190120704646"/>
			<geometry>
				<mesh filename="textured_objs/original-25.obj"/>
			</geometry>
		</visual>
		<visual name="arm_vertical_bar-95">
			<origin xyz="-0.0069497679964117265 0 -0.118190120704646"/>
			<geometry>
				<mesh filename="textured_objs/new-2.obj"/>
			</geometry>
		</visual>
		<visual name="arm_horizontal_bar-96">
			<origin xyz="-0.0069497679964117265 0 -0.118190120704646"/>
			<geometry>
				<mesh filename="textured_objs/new-3.obj"/>
			</geometry>
		</visual>
		<visual name="other_leaf-98">
			<origin xyz="-0.0069497679964117265 0 -0.118190120704646"/>
			<geometry>
				<mesh filename="textured_objs/original-8.obj"/>
			</geometry>
		</visual>
		<visual name="other_leaf-98">
			<origin xyz="-0.0069497679964117265 0 -0.118190120704646"/>
			<geometry>
				<mesh filename="textured_objs/original-28.obj"/>
			</geometry>
		</visual>
		<visual name="seat_soft_surface-93">
			<origin xyz="-0.0069497679964117265 0 -0.118190120704646"/>
			<geometry>
				<mesh filename="textured_objs/original-21.obj"/>
			</geometry>
		</visual>
		<visual name="seat_support-92">
			<origin xyz="-0.0069497679964117265 0 -0.118190120704646"/>
			<geometry>
				<mesh filename="textured_objs/original-7.obj"/>
			</geometry>
		</visual>
		<visual name="seat_support-92">
			<origin xyz="-0.0069497679964117265 0 -0.118190120704646"/>
			<geometry>
				<mesh filename="textured_objs/original-12.obj"/>
			</geometry>
		</visual>
		<visual name="central_support-61">
			<origin xyz="-0.0069497679964117265 0 -0.118190120704646"/>
			<geometry>
				<mesh filename="textured_objs/original-9.obj"/>
			</geometry>
		</visual>
		<visual name="seat_connector-65">
			<origin xyz="-0.0069497679964117265 0 -0.118190120704646"/>
			<geometry>
				<mesh filename="textured_objs/original-17.obj"/>
			</geometry>
		</visual>
		<collision>
			<origin xyz="-0.0069497679964117265 0 -0.118190120704646"/>
			<geometry>
				<mesh filename="textured_objs/original-19.obj"/>
			</geometry>
		</collision>
		<collision>
			<origin xyz="-0.0069497679964117265 0 -0.118190120704646"/>
			<geometry>
				<mesh filename="textured_objs/original-4.obj"/>
			</geometry>
		</collision>
		<collision>
			<origin xyz="-0.0069497679964117265 0 -0.118190120704646"/>
			<geometry>
				<mesh filename="textured_objs/original-26.obj"/>
			</geometry>
		</collision>
		<collision>
			<origin xyz="-0.0069497679964117265 0 -0.118190120704646"/>
			<geometry>
				<mesh filename="textured_objs/new-4.obj"/>
			</geometry>
		</collision>
		<collision>
			<origin xyz="-0.0069497679964117265 0 -0.118190120704646"/>
			<geometry>
				<mesh filename="textured_objs/new-5.obj"/>
			</geometry>
		</collision>
		<collision>
			<origin xyz="-0.0069497679964117265 0 -0.118190120704646"/>
			<geometry>
				<mesh filename="textured_objs/original-29.obj"/>
			</geometry>
		</collision>
		<collision>
			<origin xyz="-0.0069497679964117265 0 -0.118190120704646"/>
			<geometry>
				<mesh filename="textured_objs/original-16.obj"/>
			</geometry>
		</collision>
		<collision>
			<origin xyz="-0.0069497679964117265 0 -0.118190120704646"/>
			<geometry>
				<mesh filename="textured_objs/original-25.obj"/>
			</geometry>
		</collision>
		<collision>
			<origin xyz="-0.0069497679964117265 0 -0.118190120704646"/>
			<geometry>
				<mesh filename="textured_objs/new-2.obj"/>
			</geometry>
		</collision>
		<collision>
			<origin xyz="-0.0069497679964117265 0 -0.118190120704646"/>
			<geometry>
				<mesh filename="textured_objs/new-3.obj"/>
			</geometry>
		</collision>
		<collision>
			<origin xyz="-0.0069497679964117265 0 -0.118190120704646"/>
			<geometry>
				<mesh filename="textured_objs/original-8.obj"/>
			</geometry>
		</collision>
		<collision>
			<origin xyz="-0.0069497679964117265 0 -0.118190120704646"/>
			<geometry>
				<mesh filename="textured_objs/original-28.obj"/>
			</geometry>
		</collision>
		<collision>
			<origin xyz="-0.0069497679964117265 0 -0.118190120704646"/>
			<geometry>
				<mesh filename="textured_objs/original-21.obj"/>
			</geometry>
		</collision>
		<collision>
			<origin xyz="-0.0069497679964117265 0 -0.118190120704646"/>
			<geometry>
				<mesh filename="textured_objs/original-7.obj"/>
			</geometry>
		</collision>
		<collision>
			<origin xyz="-0.0069497679964117265 0 -0.118190120704646"/>
			<geometry>
				<mesh filename="textured_objs/original-12.obj"/>
			</geometry>
		</collision>
		<collision>
			<origin xyz="-0.0069497679964117265 0 -0.118190120704646"/>
			<geometry>
				<mesh filename="textured_objs/original-9.obj"/>
			</geometry>
		</collision>
		<collision>
			<origin xyz="-0.0069497679964117265 0 -0.118190120704646"/>
			<geometry>
				<mesh filename="textured_objs/original-17.obj"/>
			</geometry>
		</collision>
	</link>
	<joint name="joint_15" type="continuous">
		<origin xyz="0.0 0 0.0"/>
		<axis xyz="0 1 0"/>
		<child link="link_15"/>
		<parent link="link_15_helper"/>
	</joint>
	<link name="link_16">
		<visual name="central_support-62">
			<origin xyz="0 0 0"/>
			<geometry>
				<mesh filename="textured_objs/original-24.obj"/>
			</geometry>
		</visual>
		<visual name="central_support-63">
			<origin xyz="0 0 0"/>
			<geometry>
				<mesh filename="textured_objs/original-5.obj"/>
			</geometry>
		</visual>
		<visual name="leg-66">
			<origin xyz="0 0 0"/>
			<geometry>
				<mesh filename="textured_objs/original-20.obj"/>
			</geometry>
		</visual>
		<visual name="leg-67">
			<origin xyz="0 0 0"/>
			<geometry>
				<mesh filename="textured_objs/original-6.obj"/>
			</geometry>
		</visual>
		<visual name="leg-68">
			<origin xyz="0 0 0"/>
			<geometry>
				<mesh filename="textured_objs/original-30.obj"/>
			</geometry>
		</visual>
		<visual name="leg-69">
			<origin xyz="0 0 0"/>
			<geometry>
				<mesh filename="textured_objs/original-31.obj"/>
			</geometry>
		</visual>
		<visual name="leg-70">
			<origin xyz="0 0 0"/>
			<geometry>
				<mesh filename="textured_objs/original-32.obj"/>
			</geometry>
		</visual>
		<collision>
			<origin xyz="0 0 0"/>
			<geometry>
				<mesh filename="textured_objs/original-24.obj"/>
			</geometry>
		</collision>
		<collision>
			<origin xyz="0 0 0"/>
			<geometry>
				<mesh filename="textured_objs/original-5.obj"/>
			</geometry>
		</collision>
		<collision>
			<origin xyz="0 0 0"/>
			<geometry>
				<mesh filename="textured_objs/original-20.obj"/>
			</geometry>
		</collision>
		<collision>
			<origin xyz="0 0 0"/>
			<geometry>
				<mesh filename="textured_objs/original-6.obj"/>
			</geometry>
		</collision>
		<collision>
			<origin xyz="0 0 0"/>
			<geometry>
				<mesh filename="textured_objs/original-30.obj"/>
			</geometry>
		</collision>
		<collision>
			<origin xyz="0 0 0"/>
			<geometry>
				<mesh filename="textured_objs/original-31.obj"/>
			</geometry>
		</collision>
		<collision>
			<origin xyz="0 0 0"/>
			<geometry>
				<mesh filename="textured_objs/original-32.obj"/>
			</geometry>
		</collision>
	</link>
	<joint name="joint_16" type="fixed">
		<origin rpy="1.570796326794897 0 -1.570796326794897" xyz="0 0 0"/>
		<child link="link_16"/>
		<parent link="base"/>
	</joint>
	<link name="link_15_helper"/>
	<joint name="joint_17" type="prismatic">
		<origin xyz="0.0069497679964117265 0 0.118190120704646"/>
		<axis xyz="0 -1 0"/>
		<child link="link_15_helper"/>
		<parent link="link_16"/>
		<limit lower="0" upper="0.1"/>
	</joint>
</robot>
