<?xml version="1.0" encoding="utf-8"?>
<!-- =================================================================================== -->
<!-- |    This document was autogenerated by xacro from xarm7_robot.urdf.xacro         | -->
<!-- |    EDITING THIS FILE BY HAND IS NOT RECOMMENDED                                 | -->
<!-- =================================================================================== -->
<robot name="xarm7">
  <!--
  Author: Jimy Zhang <jimy.zhang@ufactory.cc> <jimy92@163.com>
  Contributers:
-->
  <link name="world"/>
  <joint name="world_joint" type="fixed">
    <parent link="world"/>
    <child link="link_base"/>
    <origin rpy="0 0 0" xyz="0 0 0"/>
  </joint>
  <material name="Black">
    <color rgba="0.0 0.0 0.0 1.0"/>
  </material>
  <material name="Red">
    <color rgba="0.8 0.0 0.0 1.0"/>
  </material>
  <material name="White">
    <color rgba="1.0 1.0 1.0 1.0"/>
  </material>
  <material name="Silver">
    <color rgba="0.753 0.753 0.753 1.0"/>
  </material>
  <link name="link_base">
    <inertial>
      <origin rpy="0 0 0" xyz="-0.021131 -0.0016302 0.056488"/>
      <mass value="0.88556"/>
      <inertia ixx="0.0030595" ixy="0.00012259" ixz="-0.00062705" iyy="0.0037783" iyz="0.00027023" izz="0.0020125"/>
    </inertial>
    <visual>
      <origin rpy="0 0 0" xyz="0 0 0"/>
      <geometry>
        <mesh filename="xarm_description/meshes/xarm7/visual/link_base.STL"/>
      </geometry>
      <material name="White"/>
    </visual>
    <collision>
      <origin rpy="0 0 0" xyz="0 0 0"/>
      <geometry>
        <mesh filename="xarm_description/meshes/xarm7/visual/link_base.STL"/>
      </geometry>
    </collision>
  </link>
  <link name="link1">
    <inertial>
      <origin rpy="0 0 0" xyz="-0.0042142 0.02821 -0.0087788"/>
      <mass value="0.42603"/>
      <inertia ixx="0.0014243" ixy="3.9946E-05" ixz="4.7078E-06" iyy="0.00123" iyz="-0.00026073" izz="0.00099229"/>
    </inertial>
    <visual>
      <origin rpy="0 0 0" xyz="0 0 0"/>
      <geometry>
        <mesh filename="xarm_description/meshes/xarm7/visual/link1.STL"/>
      </geometry>
      <material name="White"/>
    </visual>
    <collision>
      <origin rpy="0 0 0" xyz="0 0 0"/>
      <geometry>
        <mesh filename="xarm_description/meshes/xarm7/visual/link1.STL"/>
      </geometry>
    </collision>
  </link>
  <joint name="joint1" type="revolute">
    <origin rpy="0 0 0" xyz="0 0 0.267"/>
    <parent link="link_base"/>
    <child link="link1"/>
    <axis xyz="0 0 1"/>
    <limit effort="50" lower="-6.28318530718" upper="6.28318530718" velocity="3.14"/>
    <dynamics damping="10" friction="1"/>
  </joint>
  <link name="link2">
    <inertial>
      <origin rpy="0 0 0" xyz="-3.3178E-05 -0.12849 0.026337"/>
      <mass value="0.56095"/>
      <inertia ixx="0.0031915" ixy="3.0892E-06" ixz="2.8729E-06" iyy="0.0017468" iyz="-0.0010241" izz="0.00235"/>
    </inertial>
    <visual>
      <origin rpy="0 0 0" xyz="0 0 0"/>
      <geometry>
        <mesh filename="xarm_description/meshes/xarm7/visual/link2.STL"/>
      </geometry>
      <material name="White"/>
    </visual>
    <collision>
      <origin rpy="0 0 0" xyz="0 0 0"/>
      <geometry>
        <mesh filename="xarm_description/meshes/xarm7/visual/link2.STL"/>
      </geometry>
    </collision>
  </link>
  <joint name="joint2" type="revolute">
    <origin rpy="-1.5708 0 0" xyz="0 0 0"/>
    <parent link="link1"/>
    <child link="link2"/>
    <axis xyz="0 0 1"/>
    <limit effort="50" lower="-2.059" upper="2.0944" velocity="3.14"/>
    <dynamics damping="10" friction="1"/>
  </joint>
  <link name="link3">
    <inertial>
      <origin rpy="0 0 0" xyz="0.04223 -0.023258 -0.0096674"/>
      <mass value="0.44463"/>
      <inertia ixx="0.0011454" ixy="0.0001654" ixz="-0.0001951" iyy="0.0010503" iyz="0.00012027" izz="0.0011083"/>
    </inertial>
    <visual>
      <origin rpy="0 0 0" xyz="0 0 0"/>
      <geometry>
        <mesh filename="xarm_description/meshes/xarm7/visual/link3.STL"/>
      </geometry>
      <material name="White"/>
    </visual>
    <collision>
      <origin rpy="0 0 0" xyz="0 0 0"/>
      <geometry>
        <mesh filename="xarm_description/meshes/xarm7/visual/link3.STL"/>
      </geometry>
    </collision>
  </link>
  <joint name="joint3" type="revolute">
    <origin rpy="1.5708 0 0" xyz="0 -0.293 0"/>
    <parent link="link2"/>
    <child link="link3"/>
    <axis xyz="0 0 1"/>
    <limit effort="30" lower="-6.28318530718" upper="6.28318530718" velocity="3.14"/>
    <dynamics damping="5" friction="1"/>
  </joint>
  <link name="link4">
    <inertial>
      <origin rpy="0 0 0" xyz="0.067148 -0.10732 0.024479"/>
      <mass value="0.52387"/>
      <inertia ixx="0.0026033" ixy="0.00053379" ixz="0.00036314" iyy="0.0017649" iyz="-0.00083253" izz="0.0022431"/>
    </inertial>
    <visual>
      <origin rpy="0 0 0" xyz="0 0 0"/>
      <geometry>
        <mesh filename="xarm_description/meshes/xarm7/visual/link4.STL"/>
      </geometry>
      <material name="White"/>
    </visual>
    <collision>
      <origin rpy="0 0 0" xyz="0 0 0"/>
      <geometry>
        <mesh filename="xarm_description/meshes/xarm7/visual/link4.STL"/>
      </geometry>
    </collision>
  </link>
  <joint name="joint4" type="revolute">
    <origin rpy="1.5708 0 0" xyz="0.0525 0 0"/>
    <parent link="link3"/>
    <child link="link4"/>
    <axis xyz="0 0 1"/>
    <limit effort="30" lower="-0.19198" upper="3.927" velocity="3.14"/>
    <dynamics damping="5" friction="1"/>
  </joint>
  <link name="link5">
    <inertial>
      <origin rpy="0 0 0" xyz="-0.00023397 0.036705 -0.080064"/>
      <mass value="0.18554"/>
      <inertia ixx="0.00099549" ixy="8.9957E-07" ixz="8.5285E-07" iyy="0.0008853" iyz="-0.00025682" izz="0.00035048"/>
    </inertial>
    <visual>
      <origin rpy="0 0 0" xyz="0 0 0"/>
      <geometry>
        <mesh filename="xarm_description/meshes/xarm7/visual/link5.STL"/>
      </geometry>
      <material name="White"/>
    </visual>
    <collision>
      <origin rpy="0 0 0" xyz="0 0 0"/>
      <geometry>
        <mesh filename="xarm_description/meshes/xarm7/visual/link5.STL"/>
      </geometry>
    </collision>
  </link>
  <joint name="joint5" type="revolute">
    <origin rpy="1.5708 0 0" xyz="0.0775 -0.3425 0"/>
    <parent link="link4"/>
    <child link="link5"/>
    <axis xyz="0 0 1"/>
    <limit effort="30" lower="-6.28318530718" upper="6.28318530718" velocity="3.14"/>
    <dynamics damping="5" friction="1"/>
  </joint>
  <link name="link6">
    <inertial>
      <origin rpy="0 0 0" xyz="0.058911 0.028469 0.0068428"/>
      <mass value="0.31344"/>
      <inertia ixx="0.00052034" ixy="-0.00014989" ixz="0.00011658" iyy="0.00067968" iyz="6.116E-05" izz="0.00078345"/>
    </inertial>
    <visual>
      <origin rpy="0 0 0" xyz="0 0 0"/>
      <geometry>
        <mesh filename="xarm_description/meshes/xarm7/visual/link6.STL"/>
      </geometry>
      <material name="White"/>
    </visual>
    <collision>
      <origin rpy="0 0 0" xyz="0 0 0"/>
      <geometry>
        <mesh filename="xarm_description/meshes/xarm7/visual/link6.STL"/>
      </geometry>
    </collision>
  </link>
  <joint name="joint6" type="revolute">
    <origin rpy="1.5708 0 0" xyz="0 0 0"/>
    <parent link="link5"/>
    <child link="link6"/>
    <axis xyz="0 0 1"/>
    <limit effort="20" lower="-1.69297" upper="3.14159265359" velocity="3.14"/>
    <dynamics damping="2" friction="1"/>
  </joint>
  <link name="link7">
    <inertial>
      <origin rpy="0 0 0" xyz="-1.5846E-05 -0.0046377 -0.012705"/>
      <mass value="0.31468"/>
      <inertia ixx="0.00016985" ixy="1.1102E-07" ixz="5.1075E-08" iyy="0.00011924" iyz="-2.1251E-06" izz="0.00026032"/>
    </inertial>
    <visual>
      <origin rpy="0 0 0" xyz="0 0 0"/>
      <geometry>
        <mesh filename="xarm_description/meshes/xarm7/visual/link7.STL"/>
      </geometry>
      <material name="Silver"/>
    </visual>
    <collision>
      <origin rpy="0 0 0" xyz="0 0 0"/>
      <geometry>
        <mesh filename="xarm_description/meshes/xarm7/visual/link7.STL"/>
      </geometry>
    </collision>
  </link>
  <joint name="joint7" type="revolute">
    <origin rpy="-1.5708 0 0" xyz="0.076 0.097 0"/>
    <parent link="link6"/>
    <child link="link7"/>
    <axis xyz="0 0 1"/>
    <limit effort="20" lower="-6.28318530718" upper="6.28318530718" velocity="3.14"/>
    <dynamics damping="2" friction="1"/>
  </joint>
  <joint name="gripper_base_joint" type="fixed">
    <origin rpy="0 0 0" xyz="0 0 0"/>
    <parent link="link7"/>
    <child link="gripper_base_link"/>
    <axis xyz="0 0 0"/>
  </joint>
  <link name="gripper_base_link">
    <inertial>
      <origin rpy="0 0 0" xyz="4.03E-06 1.08E-05 0.041397"/>
      <mass value="0.1395"/>
      <inertia ixx="0.00011614" ixy="1E-08" ixz="4E-08" iyy="0.00010327" iyz="0" izz="9.707E-05"/>
    </inertial>
    <visual>
      <origin rpy="0 0 0" xyz="0 0 0"/>
      <geometry>
        <mesh filename="../kinova_gen3/kortex_description/grippers/gen3_lite_2f/meshes/gripper_base_link.STL"/>
      </geometry>
      <material name="">
        <color rgba="0.803 0.824 0.820 1"/>
      </material>
    </visual>
    <collision>
      <origin rpy="0 0 0" xyz="0 0 0"/>
      <geometry>
        <mesh filename="../kinova_gen3/kortex_description/grippers/gen3_lite_2f/meshes/gripper_base_link.STL"/>
      </geometry>
    </collision>
  </link>
  <link name="right_finger_prox_link">
    <inertial>
      <origin rpy="0 0 0" xyz="0.020257 0.0063483 6.991E-05"/>
      <mass value="0.018385"/>
      <inertia ixx="2.29E-06" ixy="1.43E-06" ixz="0" iyy="4.56E-06" iyz="0" izz="4.77E-06"/>
    </inertial>
    <visual>
      <origin rpy="0 0 0" xyz="0 0 0"/>
      <geometry>
        <mesh filename="../kinova_gen3/kortex_description/grippers/gen3_lite_2f/meshes/right_finger_prox_link.STL"/>
      </geometry>
      <material name="">
        <color rgba="0.803 0.824 0.820 1"/>
      </material>
    </visual>
    <collision>
      <origin rpy="0 0 0" xyz="0 0 0"/>
      <geometry>
        <mesh filename="../kinova_gen3/kortex_description/grippers/gen3_lite_2f/meshes/right_finger_prox_link.STL"/>
      </geometry>
    </collision>
  </link>
  <joint name="right_finger_bottom_joint" type="revolute">
    <origin rpy="0 1.5708 0" xyz="0 -0.030501 0.070003"/>
    <parent link="gripper_base_link"/>
    <child link="right_finger_prox_link"/>
    <axis xyz="0 0 1"/>
    <limit effort="1000" lower="-0.09" upper="0.96" velocity="0.6"/>
  </joint>
  <link name="right_finger_dist_link">
    <inertial>
      <origin rpy="0 0 0" xyz="0.018488 0.0011091 0"/>
      <mass value="0.010748"/>
      <inertia ixx="6.3E-03" ixy="3.2E-07" ixz="0" iyy="1.83E-03" iyz="0" izz="1.61E-03"/>
    </inertial>
    <visual>
      <origin rpy="0 0 0" xyz="0 0 0"/>
      <geometry>
        <mesh filename="../kinova_gen3/kortex_description/grippers/gen3_lite_2f/meshes/right_finger_dist_link.STL"/>
      </geometry>
      <material name="">
        <color rgba="0 0.055 0.525 1"/>
      </material>
    </visual>
    <collision>
      <origin rpy="0 0 0" xyz="0 0 0"/>
      <geometry>
        <mesh filename="../kinova_gen3/kortex_description/grippers/gen3_lite_2f/meshes/right_finger_dist_link.STL"/>
      </geometry>
    </collision>
  </link>
  <joint name="right_finger_tip_joint" type="fixed">
    <origin rpy="0 0 0.21" xyz="-0.045636 0.020423 0"/>
    <parent link="right_finger_prox_link"/>
    <child link="right_finger_dist_link"/>
    <axis xyz="0 0 1"/>
    <limit effort="1000" lower="-0.50" upper="0.21" velocity="1000"/>
    <mimic joint="right_finger_bottom_joint" multiplier="-0.676" offset="0.149"/>
  </joint>
  <link name="left_finger_prox_link">
    <inertial>
      <origin rpy="0 0 0" xyz="0.020257 0.0063483 6.99E-05"/>
      <mass value="0.018385"/>
      <inertia ixx="2.29E-03" ixy="1.43E-06" ixz="0" iyy="4.56E-03" iyz="0" izz="4.77E-03"/>
    </inertial>
    <visual>
      <origin rpy="0 0 0" xyz="0 0 0"/>
      <geometry>
        <mesh filename="../kinova_gen3/kortex_description/grippers/gen3_lite_2f/meshes/left_finger_prox_link.STL"/>
      </geometry>
      <material name="">
        <color rgba="0.803 0.824 0.820 1"/>
      </material>
    </visual>
    <collision>
      <origin rpy="0 0 0" xyz="0 0 0"/>
      <geometry>
        <mesh filename="../kinova_gen3/kortex_description/grippers/gen3_lite_2f/meshes/left_finger_prox_link.STL"/>
      </geometry>
    </collision>
  </link>
  <joint name="left_finger_bottom_joint" type="revolute">
    <origin rpy="0 1.5708 0" xyz="0 0.0305 0.070003"/>
    <parent link="gripper_base_link"/>
    <child link="left_finger_prox_link"/>
    <axis xyz="0 0 -1"/>
    <limit effort="1000" lower="-0.09" upper="0.96" velocity="1000"/>
    <mimic joint="right_finger_bottom_joint" multiplier="-1.0" offset="0.0"/>
  </joint>
  <link name="left_finger_dist_link">
    <inertial>
      <origin rpy="0 0 0" xyz="-0.018488 0.0011091 0"/>
      <mass value="0.010748"/>
      <inertia ixx="6.3E-03" ixy="3.2E-07" ixz="0" iyy="1.83E-03" iyz="0" izz="1.61E-03"/>
    </inertial>
    <visual>
      <origin rpy="0 0 0" xyz="0 0 0"/>
      <geometry>
        <mesh filename="../kinova_gen3/kortex_description/grippers/gen3_lite_2f/meshes/left_finger_dist_link.STL"/>
      </geometry>
      <material name="">
        <color rgba="0 0.055 0.525 1"/>
      </material>
    </visual>
    <collision>
      <origin rpy="0 0 0" xyz="0 0 0"/>
      <geometry>
        <mesh filename="../kinova_gen3/kortex_description/grippers/gen3_lite_2f/meshes/left_finger_dist_link.STL"/>
      </geometry>
    </collision>
  </link>
  <joint name="left_finger_tip_joint" type="fixed">
    <origin rpy="0 0 -0.21" xyz="-0.045636 -0.020423 6.9901E-05"/>
    <parent link="left_finger_prox_link"/>
    <child link="left_finger_dist_link"/>
    <axis xyz="0 0 -1"/>
    <limit effort="1000" lower="-0.50" upper="0.21" velocity="1000"/>
    <mimic joint="right_finger_bottom_joint" multiplier="-0.676" offset="0.149"/>
  </joint>
</robot>

